Traceback (most recent call last):
  File "hello.py", line 11, in <module>
    app.run(host='192.168.100.107:1007', debug=True)
  File "/opt/monitor/monitor/lib/python2.7/site-packages/flask/app.py", line 841, in run
    run_simple(host, port, self, **options)
  File "/opt/monitor/monitor/lib/python2.7/site-packages/werkzeug/serving.py", line 689, in run_simple
    s = socket.socket(address_family, socket.SOCK_STREAM)
  File "/usr/local/lib/python2.7/socket.py", line 187, in __init__
    _sock = _realsocket(family, type, proto)
socket.error: [Errno 97] Address family not supported by protocol
 * Running on http://192.168.100.107:1007/ (Press CTRL+C to quit)
 * Restarting with stat
 * Debugger is active!
 * Debugger pin code: 589-597-717
 * Running on http://192.168.100.107:1007/ (Press CTRL+C to quit)
 * Restarting with stat
 * Debugger is active!
 * Debugger pin code: 589-597-717
10.252.252.200 - - [07/Feb/2017 16:16:23] "GET / HTTP/1.1" 200 -
10.252.252.200 - - [07/Feb/2017 16:16:23] "GET /favicon.ico HTTP/1.1" 404 -
Traceback (most recent call last):
  File "hello.py", line 11, in <module>
    app.run(host='192.168.100.107', port=1007, debug=True)
  File "/usr/local/lib/python2.7/site-packages/flask/app.py", line 841, in run
    run_simple(host, port, self, **options)
  File "/usr/local/lib/python2.7/site-packages/werkzeug/serving.py", line 691, in run_simple
    s.bind((hostname, port))
  File "/usr/local/lib/python2.7/socket.py", line 224, in meth
    return getattr(self._sock,name)(*args)
socket.error: [Errno 98] Address already in use
10.11.15.218 - - [23/Feb/2017 17:01:51] "GET / HTTP/1.1" 200 -
10.11.15.218 - - [23/Feb/2017 17:01:51] "GET /favicon.ico HTTP/1.1" 404 -
10.11.15.218 - - [23/Feb/2017 17:11:54] "GET / HTTP/1.1" 200 -
10.11.15.218 - - [23/Feb/2017 17:11:54] "GET / HTTP/1.1" 200 -
  File "manage.py", line 8
    if request.method == 'POST';
                               ^
SyntaxError: invalid syntax
 * Running on http://192.168.100.107:5000/ (Press CTRL+C to quit)
 * Restarting with stat
 * Debugger is active!
 * Debugger pin code: 774-541-001
 * Running on http://192.168.100.107:5000/ (Press CTRL+C to quit)
 * Restarting with stat
 * Debugger is active!
 * Debugger pin code: 774-541-001
Traceback (most recent call last):
  File "manage.py", line 18, in <module>
    app.run(host='192.168.100.107', debug=True)
  File "/usr/local/lib/python2.7/site-packages/flask/app.py", line 841, in run
    run_simple(host, port, self, **options)
  File "/usr/local/lib/python2.7/site-packages/werkzeug/serving.py", line 691, in run_simple
    s.bind((hostname, port))
  File "/usr/local/lib/python2.7/socket.py", line 224, in meth
    return getattr(self._sock,name)(*args)
socket.error: [Errno 98] Address already in use
Traceback (most recent call last):
  File "manage.py", line 18, in <module>
    app.run(host='192.168.100.107', debug=True)
  File "/usr/local/lib/python2.7/site-packages/flask/app.py", line 841, in run
    run_simple(host, port, self, **options)
  File "/usr/local/lib/python2.7/site-packages/werkzeug/serving.py", line 691, in run_simple
    s.bind((hostname, port))
  File "/usr/local/lib/python2.7/socket.py", line 224, in meth
    return getattr(self._sock,name)(*args)
socket.error: [Errno 98] Address already in use
Traceback (most recent call last):
  File "manage.py", line 18, in <module>
    app.run(host='192.168.100.107', debug=True)
  File "/usr/local/lib/python2.7/site-packages/flask/app.py", line 841, in run
    run_simple(host, port, self, **options)
  File "/usr/local/lib/python2.7/site-packages/werkzeug/serving.py", line 691, in run_simple
    s.bind((hostname, port))
  File "/usr/local/lib/python2.7/socket.py", line 224, in meth
    return getattr(self._sock,name)(*args)
socket.error: [Errno 98] Address already in use
Traceback (most recent call last):
  File "manage.py", line 18, in <module>
    app.run(host='192.168.100.107', debug=True)
  File "/usr/local/lib/python2.7/site-packages/flask/app.py", line 841, in run
    run_simple(host, port, self, **options)
  File "/usr/local/lib/python2.7/site-packages/werkzeug/serving.py", line 691, in run_simple
    s.bind((hostname, port))
  File "/usr/local/lib/python2.7/socket.py", line 224, in meth
    return getattr(self._sock,name)(*args)
socket.error: [Errno 98] Address already in use
Traceback (most recent call last):
  File "manage.py", line 18, in <module>
    app.run(host='192.168.100.107', debug=True)
  File "/usr/local/lib/python2.7/site-packages/flask/app.py", line 841, in run
    run_simple(host, port, self, **options)
  File "/usr/local/lib/python2.7/site-packages/werkzeug/serving.py", line 691, in run_simple
    s.bind((hostname, port))
  File "/usr/local/lib/python2.7/socket.py", line 224, in meth
    return getattr(self._sock,name)(*args)
socket.error: [Errno 98] Address already in use
 * Running on http://192.168.100.107:5000/ (Press CTRL+C to quit)
 * Restarting with stat
 * Debugger is active!
 * Debugger pin code: 774-541-001
 * Running on http://192.168.100.107:9990/ (Press CTRL+C to quit)
 * Restarting with stat
 * Debugger is active!
 * Debugger pin code: 774-541-001
192.168.100.107 - - [23/Feb/2017 18:33:38] "HEAD /curl_result HTTP/1.1" 500 -
Traceback (most recent call last):
  File "/usr/local/lib/python2.7/site-packages/flask/app.py", line 1994, in __call__
    return self.wsgi_app(environ, start_response)
  File "/usr/local/lib/python2.7/site-packages/flask/app.py", line 1985, in wsgi_app
    response = self.handle_exception(e)
  File "/usr/local/lib/python2.7/site-packages/flask/app.py", line 1540, in handle_exception
    reraise(exc_type, exc_value, tb)
  File "/usr/local/lib/python2.7/site-packages/flask/app.py", line 1982, in wsgi_app
    response = self.full_dispatch_request()
  File "/usr/local/lib/python2.7/site-packages/flask/app.py", line 1614, in full_dispatch_request
    rv = self.handle_user_exception(e)
  File "/usr/local/lib/python2.7/site-packages/flask/app.py", line 1517, in handle_user_exception
    reraise(exc_type, exc_value, tb)
  File "/usr/local/lib/python2.7/site-packages/flask/app.py", line 1612, in full_dispatch_request
    rv = self.dispatch_request()
  File "/usr/local/lib/python2.7/site-packages/flask/app.py", line 1598, in dispatch_request
    return self.view_functions[rule.endpoint](**req.view_args)
  File "/opt/monitor/monitor/monitor/manage.py", line 8, in curl_result
    if request.method == 'POST':
NameError: global name 'request' is not defined
192.168.100.107 - - [23/Feb/2017 18:33:46] "GET /curl_result HTTP/1.1" 500 -
Traceback (most recent call last):
  File "/usr/local/lib/python2.7/site-packages/flask/app.py", line 1994, in __call__
    return self.wsgi_app(environ, start_response)
  File "/usr/local/lib/python2.7/site-packages/flask/app.py", line 1985, in wsgi_app
    response = self.handle_exception(e)
  File "/usr/local/lib/python2.7/site-packages/flask/app.py", line 1540, in handle_exception
    reraise(exc_type, exc_value, tb)
  File "/usr/local/lib/python2.7/site-packages/flask/app.py", line 1982, in wsgi_app
    response = self.full_dispatch_request()
  File "/usr/local/lib/python2.7/site-packages/flask/app.py", line 1614, in full_dispatch_request
    rv = self.handle_user_exception(e)
  File "/usr/local/lib/python2.7/site-packages/flask/app.py", line 1517, in handle_user_exception
    reraise(exc_type, exc_value, tb)
  File "/usr/local/lib/python2.7/site-packages/flask/app.py", line 1612, in full_dispatch_request
    rv = self.dispatch_request()
  File "/usr/local/lib/python2.7/site-packages/flask/app.py", line 1598, in dispatch_request
    return self.view_functions[rule.endpoint](**req.view_args)
  File "/opt/monitor/monitor/monitor/manage.py", line 8, in curl_result
    if request.method == 'POST':
NameError: global name 'request' is not defined
 * Detected change in '/opt/monitor/monitor/monitor/manage.py', reloading
 * Restarting with stat
  File "manage.py", line 10
    else request.method == 'GET':
               ^
SyntaxError: invalid syntax
  File "manage.py", line 11
    else request.method == 'GET':
               ^
SyntaxError: invalid syntax
Traceback (most recent call last):
  File "manage.py", line 3, in <module>
    import request
ImportError: No module named request
Traceback (most recent call last):
  File "manage.py", line 3, in <module>
    import request
ImportError: No module named request
 * Running on http://192.168.100.107:9990/ (Press CTRL+C to quit)
 * Restarting with stat
 * Debugger is active!
 * Debugger pin code: 774-541-001
192.168.100.107 - - [23/Feb/2017 18:39:16] "GET /curl_result HTTP/1.1" 500 -
Traceback (most recent call last):
  File "/usr/local/lib/python2.7/site-packages/flask/app.py", line 1994, in __call__
    return self.wsgi_app(environ, start_response)
  File "/usr/local/lib/python2.7/site-packages/flask/app.py", line 1985, in wsgi_app
    response = self.handle_exception(e)
  File "/usr/local/lib/python2.7/site-packages/flask/app.py", line 1540, in handle_exception
    reraise(exc_type, exc_value, tb)
  File "/usr/local/lib/python2.7/site-packages/flask/app.py", line 1982, in wsgi_app
    response = self.full_dispatch_request()
  File "/usr/local/lib/python2.7/site-packages/flask/app.py", line 1614, in full_dispatch_request
    rv = self.handle_user_exception(e)
  File "/usr/local/lib/python2.7/site-packages/flask/app.py", line 1517, in handle_user_exception
    reraise(exc_type, exc_value, tb)
  File "/usr/local/lib/python2.7/site-packages/flask/app.py", line 1612, in full_dispatch_request
    rv = self.dispatch_request()
  File "/usr/local/lib/python2.7/site-packages/flask/app.py", line 1598, in dispatch_request
    return self.view_functions[rule.endpoint](**req.view_args)
  File "/opt/monitor/monitor/monitor/manage.py", line 9, in curl_result
    if request.method == 'POST':
AttributeError: 'function' object has no attribute 'method'
 * Detected change in '/opt/monitor/monitor/monitor/manage.py', reloading
 * Restarting with stat
 * Debugger is active!
 * Debugger pin code: 774-541-001
192.168.100.107 - - [23/Feb/2017 18:50:08] "GET / HTTP/1.1" 404 -
192.168.100.107 - - [23/Feb/2017 18:50:21] "GET /curl_result HTTP/1.1" 200 -
192.168.100.107 - - [23/Feb/2017 18:51:29] "GET /curl_result HTTP/1.1" 200 -
 * Detected change in '/opt/monitor/monitor/monitor/manage.py', reloading
 * Restarting with stat
 * Debugger is active!
 * Debugger pin code: 774-541-001
192.168.100.107 - - [23/Feb/2017 18:51:41] "GET /curl_result HTTP/1.1" 200 -
192.168.100.107 - - [23/Feb/2017 18:52:02] "POST /curl_result HTTP/1.1" 500 -
Traceback (most recent call last):
  File "/usr/local/lib/python2.7/site-packages/flask/app.py", line 1994, in __call__
    return self.wsgi_app(environ, start_response)
  File "/usr/local/lib/python2.7/site-packages/flask/app.py", line 1985, in wsgi_app
    response = self.handle_exception(e)
  File "/usr/local/lib/python2.7/site-packages/flask/app.py", line 1540, in handle_exception
    reraise(exc_type, exc_value, tb)
  File "/usr/local/lib/python2.7/site-packages/flask/app.py", line 1982, in wsgi_app
    response = self.full_dispatch_request()
  File "/usr/local/lib/python2.7/site-packages/flask/app.py", line 1614, in full_dispatch_request
    rv = self.handle_user_exception(e)
  File "/usr/local/lib/python2.7/site-packages/flask/app.py", line 1517, in handle_user_exception
    reraise(exc_type, exc_value, tb)
  File "/usr/local/lib/python2.7/site-packages/flask/app.py", line 1612, in full_dispatch_request
    rv = self.dispatch_request()
  File "/usr/local/lib/python2.7/site-packages/flask/app.py", line 1598, in dispatch_request
    return self.view_functions[rule.endpoint](**req.view_args)
  File "/opt/monitor/monitor/monitor/manage.py", line 10, in curl_result
    wr_to_db()
  File "/opt/monitor/monitor/monitor/manage.py", line 15, in wr_to_db
    print name
NameError: global name 'name' is not defined
 * Detected change in '/opt/monitor/monitor/monitor/manage.py', reloading
 * Restarting with stat
 * Debugger is active!
 * Debugger pin code: 774-541-001
192.168.100.107 - - [23/Feb/2017 18:57:00] "POST /curl_result HTTP/1.1" 500 -
Traceback (most recent call last):
  File "/usr/local/lib/python2.7/site-packages/flask/app.py", line 1994, in __call__
    return self.wsgi_app(environ, start_response)
  File "/usr/local/lib/python2.7/site-packages/flask/app.py", line 1985, in wsgi_app
    response = self.handle_exception(e)
  File "/usr/local/lib/python2.7/site-packages/flask/app.py", line 1540, in handle_exception
    reraise(exc_type, exc_value, tb)
  File "/usr/local/lib/python2.7/site-packages/flask/app.py", line 1982, in wsgi_app
    response = self.full_dispatch_request()
  File "/usr/local/lib/python2.7/site-packages/flask/app.py", line 1614, in full_dispatch_request
    rv = self.handle_user_exception(e)
  File "/usr/local/lib/python2.7/site-packages/flask/app.py", line 1517, in handle_user_exception
    reraise(exc_type, exc_value, tb)
  File "/usr/local/lib/python2.7/site-packages/flask/app.py", line 1612, in full_dispatch_request
    rv = self.dispatch_request()
  File "/usr/local/lib/python2.7/site-packages/flask/app.py", line 1598, in dispatch_request
    return self.view_functions[rule.endpoint](**req.view_args)
  File "/opt/monitor/monitor/monitor/manage.py", line 10, in curl_result
    wr_to_db()
  File "/opt/monitor/monitor/monitor/manage.py", line 15, in wr_to_db
    print date
NameError: global name 'date' is not defined
 * Detected change in '/opt/monitor/monitor/monitor/manage.py', reloading
 * Restarting with stat
 * Debugger is active!
 * Debugger pin code: 774-541-001
192.168.100.107 - - [23/Feb/2017 18:57:49] "POST /curl_result HTTP/1.1" 500 -
Traceback (most recent call last):
  File "/usr/local/lib/python2.7/site-packages/flask/app.py", line 1994, in __call__
    return self.wsgi_app(environ, start_response)
  File "/usr/local/lib/python2.7/site-packages/flask/app.py", line 1985, in wsgi_app
    response = self.handle_exception(e)
  File "/usr/local/lib/python2.7/site-packages/flask/app.py", line 1540, in handle_exception
    reraise(exc_type, exc_value, tb)
  File "/usr/local/lib/python2.7/site-packages/flask/app.py", line 1982, in wsgi_app
    response = self.full_dispatch_request()
  File "/usr/local/lib/python2.7/site-packages/flask/app.py", line 1614, in full_dispatch_request
    rv = self.handle_user_exception(e)
  File "/usr/local/lib/python2.7/site-packages/flask/app.py", line 1517, in handle_user_exception
    reraise(exc_type, exc_value, tb)
  File "/usr/local/lib/python2.7/site-packages/flask/app.py", line 1612, in full_dispatch_request
    rv = self.dispatch_request()
  File "/usr/local/lib/python2.7/site-packages/flask/app.py", line 1598, in dispatch_request
    return self.view_functions[rule.endpoint](**req.view_args)
  File "/opt/monitor/monitor/monitor/manage.py", line 10, in curl_result
    wr_to_db()
  File "/opt/monitor/monitor/monitor/manage.py", line 15, in wr_to_db
    print "name is" + arno
NameError: global name 'arno' is not defined
 * Detected change in '/opt/monitor/monitor/monitor/manage.py', reloading
 * Restarting with stat
 * Debugger is active!
 * Debugger pin code: 774-541-001
192.168.100.107 - - [23/Feb/2017 18:59:17] "POST /curl_result HTTP/1.1" 500 -
Traceback (most recent call last):
  File "/usr/local/lib/python2.7/site-packages/flask/app.py", line 1994, in __call__
    return self.wsgi_app(environ, start_response)
  File "/usr/local/lib/python2.7/site-packages/flask/app.py", line 1985, in wsgi_app
    response = self.handle_exception(e)
  File "/usr/local/lib/python2.7/site-packages/flask/app.py", line 1540, in handle_exception
    reraise(exc_type, exc_value, tb)
  File "/usr/local/lib/python2.7/site-packages/flask/app.py", line 1982, in wsgi_app
    response = self.full_dispatch_request()
  File "/usr/local/lib/python2.7/site-packages/flask/app.py", line 1615, in full_dispatch_request
    return self.finalize_request(rv)
  File "/usr/local/lib/python2.7/site-packages/flask/app.py", line 1630, in finalize_request
    response = self.make_response(rv)
  File "/usr/local/lib/python2.7/site-packages/flask/app.py", line 1725, in make_response
    raise ValueError('View function did not return a response')
ValueError: View function did not return a response
 * Detected change in '/opt/monitor/monitor/monitor/manage.py', reloading
 * Restarting with stat
 * Debugger is active!
 * Debugger pin code: 774-541-001
192.168.100.107 - - [23/Feb/2017 19:01:18] "POST /curl_result HTTP/1.1" 500 -
Traceback (most recent call last):
  File "/usr/local/lib/python2.7/site-packages/flask/app.py", line 1994, in __call__
    return self.wsgi_app(environ, start_response)
  File "/usr/local/lib/python2.7/site-packages/flask/app.py", line 1985, in wsgi_app
    response = self.handle_exception(e)
  File "/usr/local/lib/python2.7/site-packages/flask/app.py", line 1540, in handle_exception
    reraise(exc_type, exc_value, tb)
  File "/usr/local/lib/python2.7/site-packages/flask/app.py", line 1982, in wsgi_app
    response = self.full_dispatch_request()
  File "/usr/local/lib/python2.7/site-packages/flask/app.py", line 1614, in full_dispatch_request
    rv = self.handle_user_exception(e)
  File "/usr/local/lib/python2.7/site-packages/flask/app.py", line 1517, in handle_user_exception
    reraise(exc_type, exc_value, tb)
  File "/usr/local/lib/python2.7/site-packages/flask/app.py", line 1612, in full_dispatch_request
    rv = self.dispatch_request()
  File "/usr/local/lib/python2.7/site-packages/flask/app.py", line 1598, in dispatch_request
    return self.view_functions[rule.endpoint](**req.view_args)
  File "/opt/monitor/monitor/monitor/manage.py", line 10, in curl_result
    wr_to_db()
  File "/opt/monitor/monitor/monitor/manage.py", line 15, in wr_to_db
    name = request.form.get(name)
UnboundLocalError: local variable 'name' referenced before assignment
 * Detected change in '/opt/monitor/monitor/monitor/manage.py', reloading
 * Restarting with stat
 * Debugger is active!
 * Debugger pin code: 774-541-001
192.168.100.107 - - [23/Feb/2017 19:01:51] "POST /curl_result HTTP/1.1" 500 -
Traceback (most recent call last):
  File "/usr/local/lib/python2.7/site-packages/flask/app.py", line 1994, in __call__
    return self.wsgi_app(environ, start_response)
  File "/usr/local/lib/python2.7/site-packages/flask/app.py", line 1985, in wsgi_app
    response = self.handle_exception(e)
  File "/usr/local/lib/python2.7/site-packages/flask/app.py", line 1540, in handle_exception
    reraise(exc_type, exc_value, tb)
  File "/usr/local/lib/python2.7/site-packages/flask/app.py", line 1982, in wsgi_app
    response = self.full_dispatch_request()
  File "/usr/local/lib/python2.7/site-packages/flask/app.py", line 1614, in full_dispatch_request
    rv = self.handle_user_exception(e)
  File "/usr/local/lib/python2.7/site-packages/flask/app.py", line 1517, in handle_user_exception
    reraise(exc_type, exc_value, tb)
  File "/usr/local/lib/python2.7/site-packages/flask/app.py", line 1612, in full_dispatch_request
    rv = self.dispatch_request()
  File "/usr/local/lib/python2.7/site-packages/flask/app.py", line 1598, in dispatch_request
    return self.view_functions[rule.endpoint](**req.view_args)
  File "/opt/monitor/monitor/monitor/manage.py", line 10, in curl_result
    wr_to_db()
  File "/opt/monitor/monitor/monitor/manage.py", line 15, in wr_to_db
    info = request.form.get(name)
NameError: global name 'name' is not defined
 * Detected change in '/opt/monitor/monitor/monitor/manage.py', reloading
 * Restarting with stat
 * Debugger is active!
 * Debugger pin code: 774-541-001
192.168.100.107 - - [23/Feb/2017 19:02:31] "POST /curl_result HTTP/1.1" 500 -
Traceback (most recent call last):
  File "/usr/local/lib/python2.7/site-packages/flask/app.py", line 1994, in __call__
    return self.wsgi_app(environ, start_response)
  File "/usr/local/lib/python2.7/site-packages/flask/app.py", line 1985, in wsgi_app
    response = self.handle_exception(e)
  File "/usr/local/lib/python2.7/site-packages/flask/app.py", line 1540, in handle_exception
    reraise(exc_type, exc_value, tb)
  File "/usr/local/lib/python2.7/site-packages/flask/app.py", line 1982, in wsgi_app
    response = self.full_dispatch_request()
  File "/usr/local/lib/python2.7/site-packages/flask/app.py", line 1614, in full_dispatch_request
    rv = self.handle_user_exception(e)
  File "/usr/local/lib/python2.7/site-packages/flask/app.py", line 1517, in handle_user_exception
    reraise(exc_type, exc_value, tb)
  File "/usr/local/lib/python2.7/site-packages/flask/app.py", line 1612, in full_dispatch_request
    rv = self.dispatch_request()
  File "/usr/local/lib/python2.7/site-packages/flask/app.py", line 1598, in dispatch_request
    return self.view_functions[rule.endpoint](**req.view_args)
  File "/opt/monitor/monitor/monitor/manage.py", line 10, in curl_result
    wr_to_db()
  File "/opt/monitor/monitor/monitor/manage.py", line 15, in wr_to_db
    data = request.form.get(info)
NameError: global name 'info' is not defined
 * Detected change in '/opt/monitor/monitor/monitor/manage.py', reloading
 * Restarting with stat
 * Debugger is active!
 * Debugger pin code: 774-541-001
192.168.100.107 - - [23/Feb/2017 19:03:52] "POST /curl_result HTTP/1.1" 500 -
Traceback (most recent call last):
  File "/usr/local/lib/python2.7/site-packages/flask/app.py", line 1994, in __call__
    return self.wsgi_app(environ, start_response)
  File "/usr/local/lib/python2.7/site-packages/flask/app.py", line 1985, in wsgi_app
    response = self.handle_exception(e)
  File "/usr/local/lib/python2.7/site-packages/flask/app.py", line 1540, in handle_exception
    reraise(exc_type, exc_value, tb)
  File "/usr/local/lib/python2.7/site-packages/flask/app.py", line 1982, in wsgi_app
    response = self.full_dispatch_request()
  File "/usr/local/lib/python2.7/site-packages/flask/app.py", line 1614, in full_dispatch_request
    rv = self.handle_user_exception(e)
  File "/usr/local/lib/python2.7/site-packages/flask/app.py", line 1517, in handle_user_exception
    reraise(exc_type, exc_value, tb)
  File "/usr/local/lib/python2.7/site-packages/flask/app.py", line 1612, in full_dispatch_request
    rv = self.dispatch_request()
  File "/usr/local/lib/python2.7/site-packages/flask/app.py", line 1598, in dispatch_request
    return self.view_functions[rule.endpoint](**req.view_args)
  File "/opt/monitor/monitor/monitor/manage.py", line 10, in curl_result
    wr_to_db()
  File "/opt/monitor/monitor/monitor/manage.py", line 16, in wr_to_db
    return "name is" + data['name']
TypeError: 'instancemethod' object has no attribute '__getitem__'
 * Detected change in '/opt/monitor/monitor/monitor/manage.py', reloading
 * Restarting with stat
 * Debugger is active!
 * Debugger pin code: 774-541-001
192.168.100.107 - - [23/Feb/2017 19:04:12] "POST /curl_result HTTP/1.1" 500 -
Traceback (most recent call last):
  File "/usr/local/lib/python2.7/site-packages/flask/app.py", line 1994, in __call__
    return self.wsgi_app(environ, start_response)
  File "/usr/local/lib/python2.7/site-packages/flask/app.py", line 1985, in wsgi_app
    response = self.handle_exception(e)
  File "/usr/local/lib/python2.7/site-packages/flask/app.py", line 1540, in handle_exception
    reraise(exc_type, exc_value, tb)
  File "/usr/local/lib/python2.7/site-packages/flask/app.py", line 1982, in wsgi_app
    response = self.full_dispatch_request()
  File "/usr/local/lib/python2.7/site-packages/flask/app.py", line 1614, in full_dispatch_request
    rv = self.handle_user_exception(e)
  File "/usr/local/lib/python2.7/site-packages/flask/app.py", line 1517, in handle_user_exception
    reraise(exc_type, exc_value, tb)
  File "/usr/local/lib/python2.7/site-packages/flask/app.py", line 1612, in full_dispatch_request
    rv = self.dispatch_request()
  File "/usr/local/lib/python2.7/site-packages/flask/app.py", line 1598, in dispatch_request
    return self.view_functions[rule.endpoint](**req.view_args)
  File "/opt/monitor/monitor/monitor/manage.py", line 10, in curl_result
    wr_to_db()
  File "/opt/monitor/monitor/monitor/manage.py", line 16, in wr_to_db
    return "name is" + data
TypeError: cannot concatenate 'str' and 'instancemethod' objects
 * Detected change in '/opt/monitor/monitor/monitor/manage.py', reloading
 * Restarting with stat
 * Debugger is active!
 * Debugger pin code: 774-541-001
192.168.100.107 - - [23/Feb/2017 19:04:50] "POST /curl_result HTTP/1.1" 500 -
Traceback (most recent call last):
  File "/usr/local/lib/python2.7/site-packages/flask/app.py", line 1994, in __call__
    return self.wsgi_app(environ, start_response)
  File "/usr/local/lib/python2.7/site-packages/flask/app.py", line 1985, in wsgi_app
    response = self.handle_exception(e)
  File "/usr/local/lib/python2.7/site-packages/flask/app.py", line 1540, in handle_exception
    reraise(exc_type, exc_value, tb)
  File "/usr/local/lib/python2.7/site-packages/flask/app.py", line 1982, in wsgi_app
    response = self.full_dispatch_request()
  File "/usr/local/lib/python2.7/site-packages/flask/app.py", line 1615, in full_dispatch_request
    return self.finalize_request(rv)
  File "/usr/local/lib/python2.7/site-packages/flask/app.py", line 1630, in finalize_request
    response = self.make_response(rv)
  File "/usr/local/lib/python2.7/site-packages/flask/app.py", line 1725, in make_response
    raise ValueError('View function did not return a response')
ValueError: View function did not return a response
 * Detected change in '/opt/monitor/monitor/monitor/manage.py', reloading
<bound method Request.get_data of <Request 'http://192.168.100.107:9990/curl_result' [POST]>>
 * Restarting with stat
 * Debugger is active!
 * Debugger pin code: 774-541-001
192.168.100.107 - - [23/Feb/2017 19:05:18] "POST /curl_result HTTP/1.1" 500 -
Traceback (most recent call last):
  File "/usr/local/lib/python2.7/site-packages/flask/app.py", line 1994, in __call__
    return self.wsgi_app(environ, start_response)
  File "/usr/local/lib/python2.7/site-packages/flask/app.py", line 1985, in wsgi_app
    response = self.handle_exception(e)
  File "/usr/local/lib/python2.7/site-packages/flask/app.py", line 1540, in handle_exception
    reraise(exc_type, exc_value, tb)
  File "/usr/local/lib/python2.7/site-packages/flask/app.py", line 1982, in wsgi_app
    response = self.full_dispatch_request()
  File "/usr/local/lib/python2.7/site-packages/flask/app.py", line 1615, in full_dispatch_request
    return self.finalize_request(rv)
  File "/usr/local/lib/python2.7/site-packages/flask/app.py", line 1630, in finalize_request
    response = self.make_response(rv)
  File "/usr/local/lib/python2.7/site-packages/flask/app.py", line 1725, in make_response
    raise ValueError('View function did not return a response')
ValueError: View function did not return a response
 * Detected change in '/opt/monitor/monitor/monitor/manage.py', reloading
<bound method Request.get_data of <Request 'http://192.168.100.107:9990/curl_result' [POST]>>
 * Restarting with stat
 * Debugger is active!
 * Debugger pin code: 774-541-001
192.168.100.107 - - [23/Feb/2017 19:06:19] "POST /curl_result HTTP/1.1" 200 -
 * Detected change in '/opt/monitor/monitor/monitor/manage.py', reloading
<bound method Request.get_data of <Request 'http://192.168.100.107:9990/curl_result' [POST]>>
 * Restarting with stat
 * Debugger is active!
 * Debugger pin code: 774-541-001
192.168.100.107 - - [23/Feb/2017 19:07:07] "POST /curl_result HTTP/1.1" 200 -
 * Detected change in '/opt/monitor/monitor/monitor/manage.py', reloading
 * Restarting with stat
 * Debugger is active!
 * Debugger pin code: 774-541-001
192.168.100.107 - - [23/Feb/2017 19:08:01] "POST /curl_result HTTP/1.1" 200 -
 * Detected change in '/opt/monitor/monitor/monitor/manage.py', reloading
<bound method Request.get_data of <Request 'http://192.168.100.107:9990/curl_result' [POST]>>
 * Restarting with stat
Traceback (most recent call last):
  File "manage.py", line 13, in <module>
    filemode='w'
  File "/usr/local/lib/python2.7/logging/__init__.py", line 1540, in basicConfig
    hdlr = FileHandler(filename, mode)
  File "/usr/local/lib/python2.7/logging/__init__.py", line 911, in __init__
    StreamHandler.__init__(self, self._open())
  File "/usr/local/lib/python2.7/logging/__init__.py", line 936, in _open
    stream = open(self.baseFilename, self.mode)
IOError: [Errno 2] No such file or directory: '/opt/monitor/monitor/monitor/logs/myapp.log'
Traceback (most recent call last):
  File "/usr/local/lib/python2.7/site-packages/flask/app.py", line 1994, in __call__
    return self.wsgi_app(environ, start_response)
  File "/usr/local/lib/python2.7/site-packages/flask/app.py", line 1985, in wsgi_app
    response = self.handle_exception(e)
  File "/usr/local/lib/python2.7/site-packages/flask/app.py", line 1540, in handle_exception
    reraise(exc_type, exc_value, tb)
  File "/usr/local/lib/python2.7/site-packages/flask/app.py", line 1982, in wsgi_app
    response = self.full_dispatch_request()
  File "/usr/local/lib/python2.7/site-packages/flask/app.py", line 1614, in full_dispatch_request
    rv = self.handle_user_exception(e)
  File "/usr/local/lib/python2.7/site-packages/flask/app.py", line 1517, in handle_user_exception
    reraise(exc_type, exc_value, tb)
  File "/usr/local/lib/python2.7/site-packages/flask/app.py", line 1612, in full_dispatch_request
    rv = self.dispatch_request()
  File "/usr/local/lib/python2.7/site-packages/flask/app.py", line 1598, in dispatch_request
    return self.view_functions[rule.endpoint](**req.view_args)
  File "/opt/monitor/monitor/monitor/manage.py", line 21, in curl_result
    wr_to_db()
  File "/opt/monitor/monitor/monitor/manage.py", line 27, in wr_to_db
    data = request.form.getlist()
TypeError: getlist() takes at least 2 arguments (1 given)
Traceback (most recent call last):
  File "/usr/local/lib/python2.7/site-packages/flask/app.py", line 1994, in __call__
    return self.wsgi_app(environ, start_response)
  File "/usr/local/lib/python2.7/site-packages/flask/app.py", line 1985, in wsgi_app
    response = self.handle_exception(e)
  File "/usr/local/lib/python2.7/site-packages/flask/app.py", line 1540, in handle_exception
    reraise(exc_type, exc_value, tb)
  File "/usr/local/lib/python2.7/site-packages/flask/app.py", line 1982, in wsgi_app
    response = self.full_dispatch_request()
  File "/usr/local/lib/python2.7/site-packages/flask/app.py", line 1614, in full_dispatch_request
    rv = self.handle_user_exception(e)
  File "/usr/local/lib/python2.7/site-packages/flask/app.py", line 1517, in handle_user_exception
    reraise(exc_type, exc_value, tb)
  File "/usr/local/lib/python2.7/site-packages/flask/app.py", line 1612, in full_dispatch_request
    rv = self.dispatch_request()
  File "/usr/local/lib/python2.7/site-packages/flask/app.py", line 1598, in dispatch_request
    return self.view_functions[rule.endpoint](**req.view_args)
  File "/opt/monitor/monitor/monitor/manage.py", line 21, in curl_result
    wr_to_db()
  File "/opt/monitor/monitor/monitor/manage.py", line 28, in wr_to_db
    info = eval(data)
TypeError: eval() arg 1 must be a string or code object
Traceback (most recent call last):
  File "/usr/local/lib/python2.7/site-packages/flask/app.py", line 1994, in __call__
    return self.wsgi_app(environ, start_response)
  File "/usr/local/lib/python2.7/site-packages/flask/app.py", line 1985, in wsgi_app
    response = self.handle_exception(e)
  File "/usr/local/lib/python2.7/site-packages/flask/app.py", line 1540, in handle_exception
    reraise(exc_type, exc_value, tb)
  File "/usr/local/lib/python2.7/site-packages/flask/app.py", line 1982, in wsgi_app
    response = self.full_dispatch_request()
  File "/usr/local/lib/python2.7/site-packages/flask/app.py", line 1614, in full_dispatch_request
    rv = self.handle_user_exception(e)
  File "/usr/local/lib/python2.7/site-packages/flask/app.py", line 1517, in handle_user_exception
    reraise(exc_type, exc_value, tb)
  File "/usr/local/lib/python2.7/site-packages/flask/app.py", line 1612, in full_dispatch_request
    rv = self.dispatch_request()
  File "/usr/local/lib/python2.7/site-packages/flask/app.py", line 1598, in dispatch_request
    return self.view_functions[rule.endpoint](**req.view_args)
  File "/opt/monitor/monitor/monitor/manage.py", line 21, in curl_result
    wr_to_db()
  File "/opt/monitor/monitor/monitor/manage.py", line 27, in wr_to_db
    data = request.values('content')
TypeError: 'CombinedMultiDict' object is not callable
Traceback (most recent call last):
  File "/usr/local/lib/python2.7/site-packages/flask/app.py", line 1994, in __call__
    return self.wsgi_app(environ, start_response)
  File "/usr/local/lib/python2.7/site-packages/flask/app.py", line 1985, in wsgi_app
    response = self.handle_exception(e)
  File "/usr/local/lib/python2.7/site-packages/flask/app.py", line 1540, in handle_exception
    reraise(exc_type, exc_value, tb)
  File "/usr/local/lib/python2.7/site-packages/flask/app.py", line 1982, in wsgi_app
    response = self.full_dispatch_request()
  File "/usr/local/lib/python2.7/site-packages/flask/app.py", line 1614, in full_dispatch_request
    rv = self.handle_user_exception(e)
  File "/usr/local/lib/python2.7/site-packages/flask/app.py", line 1517, in handle_user_exception
    reraise(exc_type, exc_value, tb)
  File "/usr/local/lib/python2.7/site-packages/flask/app.py", line 1612, in full_dispatch_request
    rv = self.dispatch_request()
  File "/usr/local/lib/python2.7/site-packages/flask/app.py", line 1598, in dispatch_request
    return self.view_functions[rule.endpoint](**req.view_args)
  File "/opt/monitor/monitor/monitor/manage.py", line 21, in curl_result
    wr_to_db()
  File "/opt/monitor/monitor/monitor/manage.py", line 27, in wr_to_db
    data = request.form.get()
TypeError: get() takes at least 2 arguments (1 given)
Traceback (most recent call last):
  File "/usr/local/lib/python2.7/site-packages/flask/app.py", line 1994, in __call__
    return self.wsgi_app(environ, start_response)
  File "/usr/local/lib/python2.7/site-packages/flask/app.py", line 1985, in wsgi_app
    response = self.handle_exception(e)
  File "/usr/local/lib/python2.7/site-packages/flask/app.py", line 1540, in handle_exception
    reraise(exc_type, exc_value, tb)
  File "/usr/local/lib/python2.7/site-packages/flask/app.py", line 1982, in wsgi_app
    response = self.full_dispatch_request()
  File "/usr/local/lib/python2.7/site-packages/flask/app.py", line 1614, in full_dispatch_request
    rv = self.handle_user_exception(e)
  File "/usr/local/lib/python2.7/site-packages/flask/app.py", line 1517, in handle_user_exception
    reraise(exc_type, exc_value, tb)
  File "/usr/local/lib/python2.7/site-packages/flask/app.py", line 1612, in full_dispatch_request
    rv = self.dispatch_request()
  File "/usr/local/lib/python2.7/site-packages/flask/app.py", line 1598, in dispatch_request
    return self.view_functions[rule.endpoint](**req.view_args)
  File "/opt/monitor/monitor/monitor/manage.py", line 21, in curl_result
    wr_to_db()
  File "/opt/monitor/monitor/monitor/manage.py", line 29, in wr_to_db
    logging.info(data[0])
IndexError: list index out of range
Traceback (most recent call last):
  File "/usr/local/lib/python2.7/site-packages/flask/app.py", line 1994, in __call__
    return self.wsgi_app(environ, start_response)
  File "/usr/local/lib/python2.7/site-packages/flask/app.py", line 1985, in wsgi_app
    response = self.handle_exception(e)
  File "/usr/local/lib/python2.7/site-packages/flask/app.py", line 1540, in handle_exception
    reraise(exc_type, exc_value, tb)
  File "/usr/local/lib/python2.7/site-packages/flask/app.py", line 1982, in wsgi_app
    response = self.full_dispatch_request()
  File "/usr/local/lib/python2.7/site-packages/flask/app.py", line 1614, in full_dispatch_request
    rv = self.handle_user_exception(e)
  File "/usr/local/lib/python2.7/site-packages/flask/app.py", line 1517, in handle_user_exception
    reraise(exc_type, exc_value, tb)
  File "/usr/local/lib/python2.7/site-packages/flask/app.py", line 1612, in full_dispatch_request
    rv = self.dispatch_request()
  File "/usr/local/lib/python2.7/site-packages/flask/app.py", line 1598, in dispatch_request
    return self.view_functions[rule.endpoint](**req.view_args)
  File "/opt/monitor/monitor/monitor/manage.py", line 21, in curl_result
    wr_to_db()
  File "/opt/monitor/monitor/monitor/manage.py", line 27, in wr_to_db
    data = request.form.getlist()
TypeError: getlist() takes at least 2 arguments (1 given)
Traceback (most recent call last):
  File "/usr/local/lib/python2.7/site-packages/flask/app.py", line 1994, in __call__
    return self.wsgi_app(environ, start_response)
  File "/usr/local/lib/python2.7/site-packages/flask/app.py", line 1985, in wsgi_app
    response = self.handle_exception(e)
  File "/usr/local/lib/python2.7/site-packages/flask/app.py", line 1540, in handle_exception
    reraise(exc_type, exc_value, tb)
  File "/usr/local/lib/python2.7/site-packages/flask/app.py", line 1982, in wsgi_app
    response = self.full_dispatch_request()
  File "/usr/local/lib/python2.7/site-packages/flask/app.py", line 1614, in full_dispatch_request
    rv = self.handle_user_exception(e)
  File "/usr/local/lib/python2.7/site-packages/flask/app.py", line 1517, in handle_user_exception
    reraise(exc_type, exc_value, tb)
  File "/usr/local/lib/python2.7/site-packages/flask/app.py", line 1612, in full_dispatch_request
    rv = self.dispatch_request()
  File "/usr/local/lib/python2.7/site-packages/flask/app.py", line 1598, in dispatch_request
    return self.view_functions[rule.endpoint](**req.view_args)
  File "/opt/monitor/monitor/monitor/manage.py", line 21, in curl_result
    wr_to_db()
  File "/opt/monitor/monitor/monitor/manage.py", line 29, in wr_to_db
    logging.info(data[0])
IndexError: list index out of range
Traceback (most recent call last):
  File "/usr/local/lib/python2.7/site-packages/flask/app.py", line 1994, in __call__
    return self.wsgi_app(environ, start_response)
  File "/usr/local/lib/python2.7/site-packages/flask/app.py", line 1985, in wsgi_app
    response = self.handle_exception(e)
  File "/usr/local/lib/python2.7/site-packages/flask/app.py", line 1540, in handle_exception
    reraise(exc_type, exc_value, tb)
  File "/usr/local/lib/python2.7/site-packages/flask/app.py", line 1982, in wsgi_app
    response = self.full_dispatch_request()
  File "/usr/local/lib/python2.7/site-packages/flask/app.py", line 1614, in full_dispatch_request
    rv = self.handle_user_exception(e)
  File "/usr/local/lib/python2.7/site-packages/flask/app.py", line 1517, in handle_user_exception
    reraise(exc_type, exc_value, tb)
  File "/usr/local/lib/python2.7/site-packages/flask/app.py", line 1612, in full_dispatch_request
    rv = self.dispatch_request()
  File "/usr/local/lib/python2.7/site-packages/flask/app.py", line 1598, in dispatch_request
    return self.view_functions[rule.endpoint](**req.view_args)
  File "/opt/monitor/monitor/monitor/manage.py", line 21, in curl_result
    wr_to_db()
  File "/opt/monitor/monitor/monitor/manage.py", line 29, in wr_to_db
    info="name is" + data.getlist('name')
TypeError: cannot concatenate 'str' and 'list' objects
Traceback (most recent call last):
  File "manage.py", line 25, in <module>
    @app.route('/tomcat_result', methods=['GET','POST'])
  File "/usr/local/lib/python2.7/site-packages/flask/app.py", line 1080, in decorator
    self.add_url_rule(rule, endpoint, f, **options)
  File "/usr/local/lib/python2.7/site-packages/flask/app.py", line 64, in wrapper_func
    return f(self, *args, **kwargs)
  File "/usr/local/lib/python2.7/site-packages/flask/app.py", line 1051, in add_url_rule
    'existing endpoint function: %s' % endpoint)
AssertionError: View function mapping is overwriting an existing endpoint function: curl_result
/usr/local/lib/python2.7/site-packages/sqlalchemy/engine/default.py:470: Warning: Data truncated for column 'info' at row 1
  cursor.execute(statement, parameters)
Traceback (most recent call last):
  File "manage.py", line 5, in <module>
    from db import db
  File "/opt/monitor/monitor/monitor/db/db.py", line 33, in <module>
    class mail(db.Model):
  File "/opt/monitor/monitor/monitor/db/db.py", line 35, in mail
    id = db.Column(db.Integer,primary_key=True,autoincrement=false)
NameError: name 'false' is not defined
